<?xml version="1.0" ?>
<!-- =================================================================================== -->
<!-- |    This document was autogenerated by xacro from /home/capybariana/workspace/ros2_ws/src/ex02/urdf/robot.urdf.xacro | -->
<!-- |    EDITING THIS FILE BY HAND IS NOT RECOMMENDED                                 | -->
<!-- =================================================================================== -->
<robot name="robot_hare_wheel_bot">
  <!-- === MATERIALS (defined once, referenced everywhere) === -->
  <material name="body_mat">
    <color rgba="0.6 0.6 0.7 1.0"/>
  </material>
  <material name="head_mat">
    <color rgba="0.5 0.5 0.6 1.0"/>
  </material>
  <material name="arm_mat">
    <color rgba="0.5 0.5 0.6 1.0"/>
  </material>
  <material name="ear_mat">
    <color rgba="1.0 0.9 0.2 1.0"/>
  </material>
  <material name="wheel_mat">
    <color rgba="0.1 0.1 0.1 1.0"/>
  </material>
  <!-- === BASE LINK === -->
  <link name="base_link">
    <inertial>
      <origin xyz="0 0 0.275"/>
      <mass value="3.5"/>
      <inertia ixx="0.12" ixy="0" ixz="0" iyy="0.12" iyz="0" izz="0.15"/>
    </inertial>
    <visual>
      <origin xyz="0 0 0.275"/>
      <geometry>
        <box size="0.25 0.18 0.35"/>
      </geometry>
      <material name="body_mat"/>
    </visual>
    <collision>
      <origin xyz="0 0 0.275"/>
      <geometry>
        <box size="0.25 0.18 0.35"/>
      </geometry>
    </collision>
  </link>
  <!-- === HEAD === -->
  <joint name="head_joint" type="fixed">
    <parent link="base_link"/>
    <child link="head_link"/>
    <origin xyz="0 0 0.45"/>
  </joint>
  <link name="head_link">
    <inertial>
      <origin xyz="0 0 0"/>
      <mass value="1.0"/>
      <inertia ixx="0.02" ixy="0" ixz="0" iyy="0.02" iyz="0" izz="0.02"/>
    </inertial>
    <visual>
      <origin xyz="0 0 0.06"/>
      <geometry>
        <box size="0.16 0.14 0.12"/>
      </geometry>
      <material name="head_mat"/>
    </visual>
    <collision>
      <origin xyz="0 0 0.06"/>
      <geometry>
        <box size="0.16 0.14 0.12"/>
      </geometry>
    </collision>
  </link>
  <joint name="left_ear_joint" type="fixed">
    <parent link="head_link"/>
    <child link="left_ear"/>
    <origin xyz="0 0 0"/>
  </joint>
  <link name="left_ear">
    <!-- добавлено inertial для physical properties -->
    <inertial>
      <origin xyz="0 0 0"/>
      <mass value="0.1"/>
      <inertia ixx="0.0002" ixy="0" ixz="0" iyy="0.0002" iyz="0" izz="0.0001"/>
    </inertial>
    <visual>
      <origin xyz="0 0.035 0.16"/>
      <geometry>
        <cylinder length="0.12" radius="0.03"/>
      </geometry>
      <material name="ear_mat"/>
    </visual>
    <collision>
      <origin xyz="0 0.035 0.16"/>
      <geometry>
        <cylinder length="0.12" radius="0.03"/>
      </geometry>
    </collision>
  </link>
  <joint name="right_ear_joint" type="fixed">
    <parent link="head_link"/>
    <child link="right_ear"/>
    <origin xyz="0 0 0"/>
  </joint>
  <link name="right_ear">
    <!-- добавлено inertial для physical properties -->
    <inertial>
      <origin xyz="0 0 0"/>
      <mass value="0.1"/>
      <inertia ixx="0.0002" ixy="0" ixz="0" iyy="0.0002" iyz="0" izz="0.0001"/>
    </inertial>
    <visual>
      <origin xyz="0 -0.035 0.16"/>
      <geometry>
        <cylinder length="0.12" radius="0.03"/>
      </geometry>
      <material name="ear_mat"/>
    </visual>
    <collision>
      <origin xyz="0 -0.035 0.16"/>
      <geometry>
        <cylinder length="0.12" radius="0.03"/>
      </geometry>
    </collision>
  </link>
  <joint name="left_arm_joint" type="fixed">
    <parent link="base_link"/>
    <child link="left_arm"/>
    <origin xyz="0 0 0"/>
  </joint>
  <link name="left_arm">
    <inertial>
      <origin xyz="0 0 0"/>
      <mass value="0.3"/>
      <inertia ixx="0.005" ixy="0" ixz="0" iyy="0.005" iyz="0" izz="0.005"/>
    </inertial>
    <visual>
      <origin xyz="0 0.09 0.35"/>
      <geometry>
        <box size="0.05 0.05 0.2"/>
      </geometry>
      <material name="arm_mat"/>
    </visual>
    <collision>
      <origin xyz="0 0.09 0.35"/>
      <geometry>
        <box size="0.05 0.05 0.2"/>
      </geometry>
    </collision>
  </link>
  <joint name="right_arm_joint" type="fixed">
    <parent link="base_link"/>
    <child link="right_arm"/>
    <origin xyz="0 0 0"/>
  </joint>
  <link name="right_arm">
    <inertial>
      <origin xyz="0 0 0"/>
      <mass value="0.3"/>
      <inertia ixx="0.005" ixy="0" ixz="0" iyy="0.005" iyz="0" izz="0.005"/>
    </inertial>
    <visual>
      <origin xyz="0 -0.09 0.35"/>
      <geometry>
        <box size="0.05 0.05 0.2"/>
      </geometry>
      <material name="arm_mat"/>
    </visual>
    <collision>
      <origin xyz="0 -0.09 0.35"/>
      <geometry>
        <box size="0.05 0.05 0.2"/>
      </geometry>
    </collision>
  </link>
  <joint name="left_wheel_joint" type="continuous">
    <parent link="base_link"/>
    <child link="left_wheel_link"/>
    <origin xyz="0 0.13 0.1"/>
    <axis xyz="0 1 0"/>
  </joint>
  <link name="left_wheel_link">
    <inertial>
      <origin xyz="0 0 0"/>
      <mass value="0.4"/>
      <inertia ixx="0.008" ixy="0" ixz="0" iyy="0.008" iyz="0" izz="0.008"/>
    </inertial>
    <visual>
      <origin rpy="1.5708 0 0" xyz="0 0 0"/>
      <geometry>
        <cylinder length="0.05" radius="0.1"/>
      </geometry>
      <material name="wheel_mat"/>
    </visual>
    <collision>
      <origin rpy="1.5708 0 0" xyz="0 0 0"/>
      <geometry>
        <cylinder length="0.05" radius="0.1"/>
      </geometry>
    </collision>
  </link>
  <joint name="right_wheel_joint" type="continuous">
    <parent link="base_link"/>
    <child link="right_wheel_link"/>
    <origin xyz="0 -0.13 0.1"/>
    <axis xyz="0 1 0"/>
  </joint>
  <link name="right_wheel_link">
    <inertial>
      <origin xyz="0 0 0"/>
      <mass value="0.4"/>
      <inertia ixx="0.008" ixy="0" ixz="0" iyy="0.008" iyz="0" izz="0.008"/>
    </inertial>
    <visual>
      <origin rpy="1.5708 0 0" xyz="0 0 0"/>
      <geometry>
        <cylinder length="0.05" radius="0.1"/>
      </geometry>
      <material name="wheel_mat"/>
    </visual>
    <collision>
      <origin rpy="1.5708 0 0" xyz="0 0 0"/>
      <geometry>
        <cylinder length="0.05" radius="0.1"/>
      </geometry>
    </collision>
  </link>
</robot>
