<?xml version="1.0"?>
<sdf version="1.9">
  <model name="robot_hare_wheel_bot">
    <pose>0 0 0.15 0 0 0</pose>

    <link name="base_link">
      <inertial>
        <mass>3.0</mass>
        <inertia>
          <ixx>0.05</ixx><ixy>0</ixy><ixz>0</ixz>
          <iyy>0.08</iyy><iyz>0</iyz>
          <izz>0.10</izz>
        </inertia>
      </inertial>

      <collision name="base_collision">
        <geometry><box><size>0.25 0.18 0.12</size></box></geometry>
        <pose>0 0 0.06 0 0 0</pose>
      </collision>

      <visual name="base_visual">
        <geometry><box><size>0.25 0.18 0.12</size></box></geometry>
        <pose>0 0 0.06 0 0 0</pose>
        <material>
          <ambient>0.6 0.6 0.7 1</ambient>
          <diffuse>0.6 0.6 0.7 1</diffuse>
        </material>
      </visual>
    </link>

    <link name="front_left_wheel">
      <pose>0.10 0.11 0.05 1.57079632679 0 0</pose>
      <collision name="c">
        <geometry><cylinder><radius>0.05</radius><length>0.04</length></cylinder></geometry>
      </collision>
      <visual name="v">
        <geometry><cylinder><radius>0.05</radius><length>0.04</length></cylinder></geometry>
        <material><diffuse>0.1 0.1 0.1 1</diffuse></material>
      </visual>
    </link>

    <link name="rear_left_wheel">
      <pose>-0.10 0.11 0.05 1.57079632679 0 0</pose>
      <collision name="c">
        <geometry><cylinder><radius>0.05</radius><length>0.04</length></cylinder></geometry>
      </collision>
      <visual name="v">
        <geometry><cylinder><radius>0.05</radius><length>0.04</length></cylinder></geometry>
        <material><diffuse>0.1 0.1 0.1 1</diffuse></material>
      </visual>
    </link>

    <link name="front_right_wheel">
      <pose>0.10 -0.11 0.05 1.57079632679 0 0</pose>
      <collision name="c">
        <geometry><cylinder><radius>0.05</radius><length>0.04</length></cylinder></geometry>
      </collision>
      <visual name="v">
        <geometry><cylinder><radius>0.05</radius><length>0.04</length></cylinder></geometry>
        <material><diffuse>0.1 0.1 0.1 1</diffuse></material>
      </visual>
    </link>

    <link name="rear_right_wheel">
      <pose>-0.10 -0.11 0.05 1.57079632679 0 0</pose>
      <collision name="c">
        <geometry><cylinder><radius>0.05</radius><length>0.04</length></cylinder></geometry>
      </collision>
      <visual name="v">
        <geometry><cylinder><radius>0.05</radius><length>0.04</length></cylinder></geometry>
        <material><diffuse>0.1 0.1 0.1 1</diffuse></material>
      </visual>
    </link>

    <joint name="front_left_wheel_joint" type="revolute">
      <parent>base_link</parent>
      <child>front_left_wheel</child>
      <axis><xyz>0 1 0</xyz></axis>
    </joint>

    <joint name="rear_left_wheel_joint" type="revolute">
      <parent>base_link</parent>
      <child>rear_left_wheel</child>
      <axis><xyz>0 1 0</xyz></axis>
    </joint>

    <joint name="front_right_wheel_joint" type="revolute">
      <parent>base_link</parent>
      <child>front_right_wheel</child>
      <axis><xyz>0 1 0</xyz></axis>
    </joint>

    <joint name="rear_right_wheel_joint" type="revolute">
      <parent>base_link</parent>
      <child>rear_right_wheel</child>
      <axis><xyz>0 1 0</xyz></axis>
    </joint>

    <plugin filename="gz-sim-diff-drive-system" name="gz::sim::systems::DiffDrive">
      <left_joint>front_left_wheel_joint</left_joint>
      <left_joint>rear_left_wheel_joint</left_joint>
      <right_joint>front_right_wheel_joint</right_joint>
      <right_joint>rear_right_wheel_joint</right_joint>

      <wheel_separation>0.22</wheel_separation>
      <wheel_radius>0.05</wheel_radius>

      <topic>/model/robot_hare_wheel_bot/cmd_vel</topic>
      <odom_topic>/model/robot_hare_wheel_bot/odometry</odom_topic>
      <tf_topic>/model/robot_hare_wheel_bot/tf</tf_topic>
      <frame_id>odom</frame_id>
      <child_frame_id>base_link</child_frame_id>
      <odom_publish_frequency>50</odom_publish_frequency>
    </plugin>

    <plugin filename="gz-sim-joint-state-publisher-system" name="gz::sim::systems::JointStatePublisher"/>
  </model>
</sdf>
